{
    "error": "[Errno 2] No such file or directory: '/Users/olga/Downloads/AGR-BIO-SCI_2.pdf'",
    "timestamp": 1732146155.19502,
    "current_stage": "Generating TEI/XML file",
    "traceback": "Traceback (most recent call last):\n  File \"/home/marta/Scrivania/cec/extractor/cex/combined.py\", line 782, in process_pdf\n    input_pdf_path, output_tei_path = self.create_xml_tei()\n  File \"/home/marta/Scrivania/cec/extractor/cex/combined.py\", line 895, in create_xml_tei\n    self.client.process(\"processFulltextDocument\", input_path=input_pdf_path, output=output_tei_path,\n  File \"/home/marta/Scrivania/cec/extractor/cex/grobid_client/grobid_client.py\", line 115, in process\n    self.process_batch(\n  File \"/home/marta/Scrivania/cec/extractor/cex/grobid_client/grobid_client.py\", line 233, in process_batch\n    input_file, status, text = r.result()\n  File \"/usr/lib/python3.10/concurrent/futures/_base.py\", line 451, in result\n    return self.__get_result()\n  File \"/usr/lib/python3.10/concurrent/futures/_base.py\", line 403, in __get_result\n    raise self._exception\n  File \"/usr/lib/python3.10/concurrent/futures/thread.py\", line 58, in run\n    result = self.fn(*self.args, **self.kwargs)\n  File \"/home/marta/Scrivania/cec/extractor/cex/grobid_client/grobid_client.py\", line 269, in process_pdf\n    pdf_handle = open(pdf_file, \"rb\")\nFileNotFoundError: [Errno 2] No such file or directory: '/Users/olga/Downloads/AGR-BIO-SCI_2.pdf'\n"
}